File: data/uniaxial_data_if_steel.dat
MTS793|MPT|ENU|1|2|.|/|:|1|0|0|A

Operator Informatio	Time:	89.36898	Sec	4/4/2014 1:55:08 PM
User	Luecke
Specimen	IF steel RD 4
Experiment	2014040401
material	Interstiial free steel
w 	12.638	mm
t	1.2	mm
Extensometer 1	3542-050M-050-ST G= 50mm
Extensometer 2	Instron diametral, NIST 635290
Gauge length pins free?	yes
Control Program	20140404-tension

User Test Notes	first test with Youngung
Operator Information End

Data Acquisition	Time:	224.81364	Sec	4/4/2014 1:57:23 PM
Time	Axial Displacement	Axial Force	Axial Strain
Sec	mm	N	mm/mm
122.5765	-8.1314125	-20.342424	-0.00092654198
123.57585	-8.1011992	714.84845	-0.00092654198
124.5752	-8.0776997	1403.0409	-0.00092654198
125.57455	-8.0474873	1817.6348	-0.0009198279
126.5739	-8.0206308	2040.8778	-0.00093325606
127.57324	-7.990417	2092.9116	-0.00092654198
128.5726	-7.9635611	2183.5518	-0.0009198279
129.57195	-7.9367046	2208.7295	-0.0009198279
130.57129	-7.9031343	2232.2288	-0.00092654198
131.57065	-7.8796349	2282.5842	-0.0009198279
132.56999	-7.8460646	2287.6199	-0.0009198279
133.56934	-7.8192081	2331.2615	-0.0009198279
134.5687	-7.7923522	2351.4036	-0.00092654198
135.56804	-7.7621388	2361.4749	-0.00093325606
136.56738	-7.7319255	2371.5459	-0.00092654198
137.56674	-7.7050691	2420.2227	-0.00092654198
138.56609	-7.6748557	2400.0806	-0.00093325606
139.56543	-7.6446424	2435.3293	-0.00093325606
140.56479	-7.6177864	2473.9353	-0.00093325606
141.56413	-7.59093	2457.1501	-0.00093325606
142.56348	-7.5607166	2475.6138	-0.00092654198
143.56284	-7.5305033	2507.5056	-0.00092654198
144.56218	-7.5002899	2532.6833	-0.00093325606
145.56152	-7.4767909	2531.0049	-0.0009198279
146.56088	-7.4465775	2556.1826	-0.00092654198
147.56023	-7.4197211	2579.6819	-0.00092654198
148.55957	-7.3895078	2599.8242	-0.0009198279
149.55893	-7.3592944	2609.8953	-0.00092654198
150.55827	-7.3357949	2630.0376	-0.00093325606
151.55762	-7.305582	2651.8584	-0.00093325606
152.55698	-7.2720113	2646.8228	-0.00093325606
153.55632	-7.2451553	2655.2153	-0.00092654198
154.55566	-7.2182989	2675.3577	-0.00092654198
155.55502	-7.1880856	2707.2495	-0.0009198279
156.55437	-7.1612291	2722.3562	-0.00093325606
157.55371	-7.1310158	2724.0347	-0.00091311382
158.55307	-7.1041598	2735.7839	-0.00092654198
159.55241	-7.0705895	2745.8552	-0.00092654198
160.55176	-7.050447	2786.1396	-0.00092654198
161.55112	-7.0202336	2771.033	-0.00092654198
162.55046	-6.9933777	2782.7825	-0.00092654198
163.5498	-6.9631643	2806.2817	-0.0009198279
164.54916	-6.9295936	2834.8167	-0.00092654198
165.54851	-6.9027376	2846.5664	-0.00093325606
166.54785	-6.8758812	2831.4597	-0.0009198279
167.54721	-6.8490248	2841.5308	-0.00092654198
168.54655	-6.8188114	2848.2449	-0.00092654198
169.5459	-6.7919555	2853.2805	-0.00093325606
170.54526	-6.765099	2863.3516	-0.0009198279
171.5446	-6.7315288	2905.3145	-0.00093325606
172.54395	-6.7013154	2945.5989	-0.00092654198
173.5433	-6.6778159	2925.4568	-0.0009198279
174.54265	-6.6442456	2906.9929	-0.00093325606
175.54199	-6.6173897	2937.2063	-0.00092654198
176.54135	-6.5905333	2940.5635	-0.00093325606
177.5407	-6.5636768	2933.8494	-0.00092654198
178.54004	-6.5301065	2979.1694	-0.00092654198
179.5394	-6.5032501	2982.5264	-0.00092654198
180.53874	-6.4730368	3000.99	-0.0009198279
181.53809	-6.4461808	3000.99	-0.00093325606
182.53745	-6.4193244	3027.8464	-0.00093325606
183.53679	-6.392468	3026.168	-0.00093325606
184.53613	-6.3622546	3034.5605	-0.00093325606
185.53549	-6.3320413	3036.239	-0.00092654198
186.53484	-6.3018279	3053.0242	-0.00093325606
187.53418	-6.274972	3078.2017	-0.00093325606
188.53354	-6.2447586	3063.0952	-0.00092654198
189.53288	-6.2179022	3059.7383	-0.00092654198
190.53223	-6.1944027	3089.9514	-0.00093325606
191.53159	-6.1608324	3086.5942	-0.00093325606
192.53093	-6.1272621	3118.4861	-0.00092654198
193.53027	-6.1004057	3111.7722	-0.0009198279
194.52963	-6.0735497	3123.5217	-0.00091311382
195.52898	-6.0500503	3105.0581	-0.0009198279
196.52832	-6.0231938	3135.2715	-0.0009198279
197.52768	-5.9862666	3148.6995	-0.00093325606
198.52702	-5.9594102	3150.3782	-0.00093325606
199.52637	-5.9325542	3170.5203	-0.00092654198
200.52573	-5.9056978	3178.9128	-0.00090639974
201.52507	-5.8788414	3162.1277	-0.00093325606
202.52441	-5.848628	3183.9485	-0.0009198279
203.52377	-5.8150578	3172.1987	-0.0009198279
204.52312	-5.7915587	3222.5544	-0.00092654198
205.52246	-5.7613454	3197.3767	-0.00092654198
206.52182	-5.734489	3227.5898	-0.00092654198
207.52116	-5.7042756	3269.553	-0.00092654198
208.52051	-5.6774192	3266.1958	-0.00092654198
209.51987	-5.6438489	3247.7322	-0.0009198279
210.51921	-5.6169925	3242.6965	-0.0009198279
211.51855	-5.5901365	3261.1604	-0.0009198279
212.51791	-5.5632801	3262.8389	-0.00092654198
213.51726	-5.5330667	3271.2314	-0.00093325606
214.5166	-5.5028534	3266.1958	-0.00093325606
215.51596	-5.47264	3291.3738	-0.00092654198
216.5153	-5.4457841	3304.8018	-0.00093325606
217.51465	-5.4155707	3298.0876	-0.00093325606
218.51401	-5.3920712	3313.1943	-0.0009198279
219.51335	-5.3618579	3324.9441	-0.00092654198
220.5127	-5.3316445	3316.5515	-0.00093325606
221.51205	-5.3081455	3351.8003	-0.00093325606
222.5114	-5.2812891	3331.6582	-0.00093325606
223.51074	-5.2443619	3341.7292	-0.00093325606
224.5101	-5.2175055	3314.873	-0.0009198279
225.50945	-5.1839352	3366.907	-0.00092654198
226.50879	-5.16715	3363.55	-0.00093325606
227.50815	-5.1335797	3375.2996	-0.00092654198
228.50749	-5.1033664	3365.2285	-0.00093325606
229.50684	-5.07651	3407.1912	-0.00092654198
230.5062	-5.0462966	3380.3352	-0.00092654198
231.50554	-5.0160832	3402.1558	-0.00092654198
232.50488	-4.9925842	3422.2979	-0.00092654198
233.50424	-4.9590135	3439.083	-0.00092654198
234.50359	-4.9355145	3427.3335	-0.00092654198
235.50293	-4.908658	3418.9409	-0.00089297158
236.50229	-4.8717308	3420.6194	-0.00087282941
237.50163	-4.8482313	3429.012	-0.00087954348
238.50098	-4.8247323	3449.1543	-0.00087954348
239.50034	-4.7945189	3449.1543	-0.00088625751
240.49968	-4.7643056	3472.6536	-0.00088625751
241.49902	-4.7340922	3464.261	-0.00088625751
242.49838	-4.7038789	3474.332	-0.00087954348
243.49773	-4.6736655	3465.9395	-0.00088625751
244.49707	-4.6501665	3484.4031	-0.00087954348
245.49643	-4.6165957	3494.4744	-0.00087954348
246.49577	-4.5897398	3502.8669	-0.00087954348
247.49512	-4.5595264	3517.9736	-0.00088625751
248.49448	-4.53267	3506.2239	-0.00087954348
249.49382	-4.5058136	3514.6165	-0.00087954348
250.49316	-4.4756002	3543.1514	-0.00087954348
251.49252	-4.4453874	3541.4729	-0.00087282941
252.49187	-4.4185309	3526.3662	-0.00088625751
253.49121	-4.3916745	3553.2224	-0.00087954348
254.49057	-4.3648181	3548.1868	-0.00089297158
255.48991	-4.3346047	3554.9009	-0.00088625751
256.48926	-4.3043914	3559.9365	-0.00087954348
257.48862	-4.2741785	3548.1868	-0.00088625751
258.48798	-4.250679	3563.2935	-0.00089968566
259.4873	-4.2137518	3575.0432	-0.00088625751
260.48666	-4.1902523	3578.4001	-0.00087954348
261.48602	-4.1600389	3593.5068	-0.00089297158
262.48535	-4.133183	3575.0432	-0.00089297158
263.48471	-4.1029696	3601.8994	-0.00087954348
264.48407	-4.0727563	3600.2209	-0.00088625751
265.4834	-4.0526137	3591.8284	-0.00089297158
266.48276	-4.0224004	3628.7559	-0.00088625751
267.48212	-3.9955442	3591.8284	-0.00089297158
268.48145	-3.9653311	3633.7913	-0.00089297158
269.4808	-3.9351177	3620.3633	-0.00088625751
270.48016	-3.9049044	3635.47	-0.00088625751
271.47949	-3.8780479	3633.7913	-0.00088625751
272.47885	-3.8511918	3648.8979	-0.00089297158
273.47821	-3.8142643	3643.8625	-0.00088625751
274.47754	-3.790765	3650.5767	-0.00088625751
275.4769	-3.7605517	3660.6477	-0.00088625751
276.47626	-3.7370524	3675.7544	-0.00088625751
277.47559	-3.7068391	3658.9692	-0.00088625751
278.47495	-3.676626	3674.0759	-0.00089297158
279.4743	-3.6464126	3657.2905	-0.00088625751
280.47363	-3.6195562	3690.8611	-0.00089297158
281.47299	-3.5893428	3682.4685	-0.00089297158
282.47235	-3.5624866	3695.8965	-0.00088625751
283.47168	-3.5322733	3697.5752	-0.00089297158
284.47104	-3.5054171	3689.1826	-0.00087954348
285.4704	-3.4785607	3694.218	-0.00088625751
286.46973	-3.4483473	3690.8611	-0.00088625751
287.46909	-3.4214911	3699.2537	-0.00088625751
288.46844	-3.3879209	3709.3247	-0.00089297158
289.46777	-3.3610644	3717.7173	-0.00087954348
290.46713	-3.3308511	3726.1099	-0.00087954348
291.46649	-3.3073518	3732.8237	-0.00088625751
292.46582	-3.2771385	3711.0032	-0.00088625751
293.46518	-3.2502823	3751.2874	-0.00087954348
294.46454	-3.2234261	3742.8948	-0.00088625751
295.46387	-3.1932127	3752.9661	-0.00088625751
296.46323	-3.1596422	3754.6445	-0.00088625751
297.46259	-3.132786	3764.7156	-0.00088625751
298.46191	-3.1059299	3766.394	-0.00088625751
299.46127	-3.0790734	3761.3586	-0.00089968566
300.46063	-3.0555742	3756.323	-0.00087954348
301.45996	-3.0220039	3749.6089	-0.00088625751
302.45932	-2.9917905	3763.0371	-0.00088625751
303.45868	-2.9682913	3801.6431	-0.00089297158
304.45801	-2.934721	3778.1438	-0.00090639974
305.45737	-2.9045076	3774.7866	-0.00088625751
306.45673	-2.8776512	3793.2505	-0.00089297158
307.45605	-2.8474379	3774.7866	-0.00088625751
308.45541	-2.8205817	3799.9646	-0.00087282941
309.45477	-2.7903683	3808.3572	-0.00087954348
310.4541	-2.760155	3815.0713	-0.00087954348
311.45346	-2.7332988	3810.0356	-0.00089297158
312.45282	-2.7030854	3823.4639	-0.00089297158
313.45215	-2.6795862	3820.1067	-0.00088625751
314.45151	-2.6493728	3823.4639	-0.00088625751
315.45087	-2.6191595	3818.4282	-0.00089297158
316.4502	-2.5923033	3821.7852	-0.00088625751
317.44955	-2.5654469	3821.7852	-0.00088625751
318.44891	-2.5352337	3836.8918	-0.00088625751
319.44824	-2.5083773	3840.249	-0.00088625751
320.4476	-2.4815211	3838.5706	-0.00087282941
321.44696	-2.4479506	3841.9275	-0.00088625751
322.44629	-2.4210944	3838.5706	-0.00087282941
323.44565	-2.394238	3835.2134	-0.00087282941
324.44501	-2.3640249	3873.8193	-0.00088625751
325.44434	-2.3371685	3838.5706	-0.00089968566
326.4437	-2.3103123	3853.6772	-0.00089297158
327.44305	-2.2800989	3858.7126	-0.00087954348
328.44238	-2.2532425	3862.0698	-0.00089297158
329.44174	-2.2230294	3865.4268	-0.00088625751
330.4411	-2.192816	3858.7126	-0.00088625751
331.44043	-2.1626027	3875.4978	-0.00089968566
332.43979	-2.1357462	3875.4978	-0.00087282941
333.43915	-2.1088901	3865.4268	-0.00087954348
334.43848	-2.0786767	3877.1765	-0.00088625751
335.43784	-2.0484633	3888.926	-0.00087954348
336.43719	-2.0216072	3878.855	-0.00088625751
337.43652	-1.9913938	3878.855	-0.00089297158
338.43588	-1.9611804	3900.6758	-0.00087954348
339.43524	-1.9343241	3909.0684	-0.00087954348
340.43457	-1.9074678	3907.3896	-0.00087954348
341.43393	-1.8772546	3898.9971	-0.00088625751
342.43329	-1.8503983	3922.4963	-0.00088625751
343.43262	-1.8168279	3924.175	-0.00088625751
344.43198	-1.7933286	3919.1394	-0.00088625751
345.43134	-1.7631153	3914.1038	-0.00088625751
346.43066	-1.739616	3922.4963	-0.00089297158
347.43002	-1.7060457	3945.9956	-0.00088625751
348.42938	-1.6724753	3940.9602	-0.00087954348
349.42871	-1.6489761	3954.3882	-0.00089297158
350.42807	-1.6221198	3939.2817	-0.00088625751
351.42743	-1.5952635	3937.603	-0.00089297158
352.42676	-1.5583361	3939.2817	-0.00088625751
353.42612	-1.5348369	3952.7097	-0.00087954348
354.42548	-1.5046235	3954.3882	-0.00089297158
355.4248	-1.4777672	3962.781	-0.00088625751
356.42416	-1.4509109	3967.8164	-0.00089297158
357.42352	-1.4173406	3962.781	-0.00088625751
358.42285	-1.3871273	3967.8164	-0.00089297158
359.42221	-1.363628	3981.2446	-0.00088625751
360.42157	-1.3334147	3971.1736	-0.00089968566
361.4209	-1.3065584	3974.5305	-0.00089297158
362.42026	-1.2797022	3984.6016	-0.00087954348
363.41962	-1.2494888	3992.9941	-0.00089297158
364.41895	-1.2192755	3979.5662	-0.00089297158
365.4183	-1.1924192	3984.6016	-0.00089297158
366.41766	-1.1622059	3986.2803	-0.00088625751
367.41699	-1.1353496	3991.3157	-0.00088625751
368.41635	-1.1084933	3986.2803	-0.00088625751
369.41571	-1.07828	3989.6372	-0.00088625751
370.41504	-1.0547807	3998.0298	-0.00089968566
371.4144	-1.0212103	3987.9587	-0.00088625751
372.41376	-0.99435407	3986.2803	-0.00089297158
373.41309	-0.95742667	3989.6372	-0.00089968566
374.41245	-0.93728447	3998.0298	-0.00089297158
375.4118	-0.90707111	4004.7437	-0.00089297158
376.41113	-0.88021487	3998.0298	-0.00088625751
377.41049	-0.85335857	3996.3513	-0.00088625751
378.40985	-0.81978822	4028.2432	-0.00089297158
379.40918	-0.79293191	4013.1365	-0.00087282941
380.40854	-0.76271862	4009.7795	-0.00088625751
381.4079	-0.73586231	4014.8149	-0.00089297158
382.40723	-0.70900601	4003.0652	-0.00089297158
383.40659	-0.67879272	4011.458	-0.00087954348
384.40594	-0.65193641	4019.8503	-0.00088625751
385.40527	-0.62172306	4033.2786	-0.00089297158
386.40463	-0.59150976	4028.2432	-0.00089297158
387.40399	-0.56801051	4021.5293	-0.00088625751
388.40332	-0.53779715	4023.2078	-0.00089297158
389.40268	-0.5042268	4036.6355	-0.00087954348
390.40204	-0.47737053	4039.9929	-0.00088625751
391.40137	-0.45387128	4031.6001	-0.00088625751
392.40073	-0.4203009	4036.6355	-0.00087282941
393.40009	-0.39680165	4036.6355	-0.00089297158
394.39941	-0.3632313	4029.9216	-0.00088625751
395.39877	-0.33637503	4055.0996	-0.00088625751
396.39813	-0.30280465	4050.0637	-0.00087954348
397.39746	-0.27594838	4051.7422	-0.00087954348
398.39682	-0.24909207	4078.5984	-0.00087954348
399.39618	-0.22223578	4051.7422	-0.00087954348
400.39551	-0.1953795	4055.0996	-0.00087954348
401.39487	-0.16516617	4046.7068	-0.00087954348
402.39423	-0.13159582	4076.9199	-0.00088625751
403.39355	-0.10809656	4076.9199	-0.00089968566
404.39291	-0.074526206	4092.0266	-0.00087954348
405.39227	-0.051010165	4071.8845	-0.00088625751
406.3916	-0.020645766	4073.563	-0.00088625751
407.39096	0.0063448106	4073.563	-0.00087282941
408.39032	0.040083032	4083.6338	-0.00087954348
409.38965	0.060325962	4097.062	-0.00087282941
410.38901	0.094064184	4090.3481	-0.00087282941
411.38837	0.12105476	4093.7051	-0.00087954348
412.3877	0.15141916	4098.7407	-0.00087282941
413.38705	0.17503591	4081.9553	-0.00089297158
414.38641	0.2054003	4110.4902	-0.00087954348
415.38574	0.23913853	4073.563	-0.00087954348
416.3851	0.26275527	4115.5264	-0.00087954348
417.38446	0.28974587	4098.7407	-0.00088625751
418.38379	0.31673643	4115.5264	-0.00087954348
419.38315	0.35384849	4112.1689	-0.00088625751
420.38251	0.37746522	4108.812	-0.00087954348
421.38184	0.40782964	4112.1689	-0.00087282941
422.3812	0.43144637	4095.3835	-0.00088625751
423.38055	0.4651846	4110.4902	-0.00088625751
424.37988	0.49217519	4105.4551	-0.00087954348
425.37924	0.51916575	4123.9185	-0.00087282941
426.3786	0.54953015	4110.4902	-0.00089297158
427.37793	0.57989454	4083.6338	-0.00087282941
428.37729	0.60688514	4107.1333	-0.00087282941
429.37665	0.63724953	4108.812	-0.00087954348
430.37598	0.66424012	4108.812	-0.00087954348
431.37534	0.68785685	4122.2402	-0.00087954348
432.37469	0.72834271	4113.8472	-0.00088625751
433.37402	0.74858564	4120.5615	-0.00087282941
434.37338	0.77557623	4113.8472	-0.00088625751
435.37274	0.80256683	4100.4194	-0.00087954348
436.37207	0.83630502	4103.7764	-0.00089297158
437.37143	0.86329561	4140.7036	-0.00088625751
438.37079	0.89028615	4117.2046	-0.00088625751
439.37012	0.91727674	4102.0981	-0.00088625751
440.36948	0.951015	4118.8833	-0.00087954348
441.36884	0.97463173	4117.2046	-0.00087954348
442.36816	1.0049962	4105.4551	-0.00089297158
443.36752	1.0319867	4122.2402	-0.00088625751
444.36688	1.0623511	4123.9185	-0.00088625751
445.36621	1.0927155	4139.0254	-0.00087954348
446.36557	1.119706	4135.6685	-0.00087954348
447.36493	1.1466967	4142.3823	-0.00088625751
448.36426	1.1770611	4139.0254	-0.00088625751
449.36362	1.2074255	4157.4888	-0.00087954348
450.36298	1.2411636	4144.0605	-0.00088625751
451.3623	1.2647804	4169.2388	-0.00087954348
452.36166	1.2917711	4149.0967	-0.00087282941
453.36102	1.3187616	4155.8105	-0.00089297158
454.36035	1.3457521	4159.1675	-0.00089297158
455.35971	1.3727428	4127.2754	-0.00089297158
456.35907	1.4064809	4150.7749	-0.00087954348
457.3584	1.4334716	4157.4888	-0.00087954348
458.35776	1.4604621	4140.7036	-0.00089297158
459.35712	1.4908265	4160.8457	-0.00087954348
460.35645	1.5245647	4172.5957	-0.00089297158
461.3558	1.5481814	4150.7749	-0.00089297158
462.35516	1.5751721	4175.9526	-0.00088625751
463.35449	1.6055365	4149.0967	-0.00088625751
464.35385	1.6359009	4154.1318	-0.00089297158
465.35321	1.6595176	4154.1318	-0.00087954348
466.35254	1.6932558	4160.8457	-0.00089297158
467.3519	1.7202464	4159.1675	-0.00087954348
468.35126	1.747237	4184.3452	-0.00087954348
469.35059	1.7776014	4162.5249	-0.00087954348
470.34995	1.8045919	4187.7021	-0.00087954348
471.3493	1.8349563	4192.7378	-0.00088625751
472.34863	1.8653207	4194.4165	-0.00088625751
473.34799	1.8923113	4164.2031	-0.00087282941
474.34735	1.9193019	4160.8457	-0.00087282941
475.34668	1.9462925	4162.5249	-0.00087954348
476.34604	1.9766569	4187.7021	-0.00087954348
477.3454	2.0070212	4196.0952	-0.00087282941
478.34473	2.0340118	4196.0952	-0.00088625751
479.34409	2.0610025	4186.0239	-0.00088625751
480.34344	2.0913668	4186.0239	-0.00088625751
481.34277	2.1217313	4194.4165	-0.00087954348
482.34213	2.1520956	4179.3101	-0.00088625751
483.34149	2.1723385	4187.7021	-0.00087954348
484.34082	2.2060769	4199.4521	-0.00087954348
485.34018	2.2330673	4194.4165	-0.00089297158
486.33954	2.2600579	4177.6313	-0.00087954348
487.33887	2.2937961	4177.6313	-0.00088625751
488.33823	2.3207867	4206.166	-0.00087954348
489.33759	2.3477774	4186.0239	-0.00087954348
490.33691	2.3781416	4175.9526	-0.00087282941
491.33627	2.4051323	4201.1304	-0.00088625751
492.33563	2.4321229	4197.7734	-0.00087954348
493.33496	2.4624872	4202.8091	-0.00086611533
494.33432	2.4894779	4217.9155	-0.00089297158
495.33368	2.5198421	4189.3809	-0.00087282941
496.33301	2.5502067	4187.7021	-0.00088625751
497.33237	2.5771971	4170.917	-0.00088625751
498.33173	2.6041877	4207.8442	-0.00087282941
499.33105	2.6345522	4217.9155	-0.00087954348
500.33041	2.6581688	4211.2017	-0.00087954348
501.32977	2.6919072	4211.2017	-0.00088625751
502.3291	2.7222714	4207.8442	-0.00089297158
503.32846	2.7458882	4219.5942	-0.00089297158
504.32782	2.7728789	4226.3081	-0.00088625751
505.32715	2.8032432	4192.7378	-0.00089297158
506.32651	2.82686	4199.4521	-0.00089297158
507.32587	2.8639719	4221.2725	-0.00087954348
508.3252	2.8909626	4186.0239	-0.00089297158
509.32455	2.9179533	4221.2725	-0.00089297158
510.32391	2.9483175	4219.5942	-0.00087954348
511.32324	2.978682	4212.8804	-0.00087954348
512.32263	3.0056727	4201.1304	-0.00089968566
513.32196	3.0326631	4202.8091	-0.00089968566
514.32129	3.0630276	4222.9512	-0.00089968566
515.32068	3.090018	4227.9868	-0.00090639974
516.32001	3.1237564	4199.4521	-0.00088625751
517.31934	3.1473732	4239.7358	-0.00088625751
518.31873	3.1777375	4229.665	-0.00087282941
519.31805	3.2047281	4207.8442	-0.00087954348
520.31738	3.2317185	4216.2373	-0.00087282941
521.31677	3.2620831	4249.8071	-0.00088625751
522.3161	3.2924473	4243.0933	-0.00088625751
523.31543	3.319438	4222.9512	-0.00087954348
524.31482	3.3498025	4236.3789	-0.00089968566
525.31415	3.3801668	4241.415	-0.00089297158
526.31348	3.4071574	4244.772	-0.00089297158
527.31287	3.4341481	4236.3789	-0.00087954348
528.31219	3.4678862	4222.9512	-0.00088625751
529.31152	3.4881291	4234.7007	-0.00089297158
530.31091	3.5184934	4249.8071	-0.00088625751
531.31024	3.5488579	4253.1641	-0.00088625751
532.30957	3.5792222	4231.3438	-0.00089297158
533.30896	3.602839	4229.665	-0.00088625751
534.30829	3.6298296	4238.0576	-0.00088625751
535.30762	3.6568203	4249.8071	-0.00089297158
536.30701	3.6905584	4244.772	-0.00089297158
537.30634	3.7209229	4231.3438	-0.00087954348
538.30566	3.7512872	4231.3438	-0.00089297158
539.30505	3.774904	4233.022	-0.00089968566
540.30438	3.8052683	4251.4858	-0.00087282941
541.30371	3.8356328	4253.1641	-0.00089297158
542.3031	3.8558757	4243.0933	-0.00087954348
543.30243	3.88624	4229.665	-0.00089297158
544.30176	3.9166045	4234.7007	-0.00089297158
545.30115	3.946969	4249.8071	-0.00088625751
546.30048	3.9773333	4253.1641	-0.00088625751
547.2998	4.004324	4269.9492	-0.00089297158
548.29919	4.0346885	4254.8428	-0.00088625751
549.29852	4.0650525	4253.1641	-0.00087954348
550.29785	4.0886693	4258.2002	-0.00089968566
551.29724	4.1156602	4243.0933	-0.00089968566
552.29657	4.1493983	4251.4858	-0.00087954348
553.2959	4.1797628	4239.7358	-0.00087954348
554.29529	4.2101269	4259.8784	-0.00087282941
555.29462	4.2337437	4258.2002	-0.00088625751
556.29395	4.2641082	4273.3066	-0.00088625751
557.29333	4.2910986	4261.5571	-0.00087954348
558.29266	4.3147154	4244.772	-0.00089297158
559.29199	4.3484535	4264.9141	-0.00089297158
560.29138	4.3754444	4241.415	-0.00088625751
561.29071	4.4091825	4259.8784	-0.00088625751
562.29004	4.4294252	4271.6284	-0.00088625751
563.28943	4.4597898	4264.9141	-0.00088625751
564.28876	4.4935279	4264.9141	-0.00087954348
565.28809	4.5171447	4251.4858	-0.00089297158
566.28748	4.5475092	4246.4502	-0.00089297158
567.2868	4.5744996	4249.8071	-0.00088625751
568.28613	4.6014905	4269.9492	-0.00088625751
569.28552	4.631855	4251.4858	-0.00088625751
570.28485	4.662219	4274.9854	-0.00088625751
571.28418	4.6858358	4298.4844	-0.00089297158
572.28357	4.719574	4244.772	-0.00088625751
573.2829	4.7431908	4258.2002	-0.00089297158
574.28223	4.780303	4261.5571	-0.00087954348
575.28162	4.8072934	4273.3066	-0.00089297158
576.28094	4.8376579	4259.8784	-0.00088625751
577.28027	4.8612747	4251.4858	-0.00089297158
578.27966	4.8882651	4248.1289	-0.00087954348
579.27899	4.9186296	4269.9492	-0.00087954348
580.27832	4.9422464	4269.9492	-0.00089297158
581.27771	4.9793587	4269.9492	-0.00088625751
582.27704	5.002975	4278.3423	-0.00087954348
583.27637	5.0367136	4264.9141	-0.00087954348
584.27576	5.0603304	4261.5571	-0.00089297158
585.27509	5.0906944	4266.5923	-0.00088625751
586.27441	5.1210589	4266.5923	-0.00089297158
587.2738	5.1514235	4269.9492	-0.00088625751
588.27313	5.1716661	4268.271	-0.00087954348
589.27246	5.2087784	4264.9141	-0.00089297158
590.27185	5.2323952	4278.3423	-0.00088625751
591.27118	5.2593856	4286.7344	-0.00087954348
592.27051	5.2897501	4264.9141	-0.00088625751
593.2699	5.3133669	4281.6992	-0.00089297158
594.26923	5.3504786	4281.6992	-0.00088625751
595.26855	5.3740954	4276.6636	-0.00088625751
596.26794	5.40446	4301.8413	-0.00087954348
597.26727	5.4280767	4306.877	-0.00087954348
598.2666	5.4618149	4266.5923	-0.00087954348
599.26599	5.4888058	4291.7705	-0.00088625751
600.26532	5.5225439	4301.8413	-0.00088625751
601.26465	5.5461607	4261.5571	-0.00087282941
602.26404	5.5765247	4280.0205	-0.00088625751
603.26337	5.6035156	4286.7344	-0.00087954348
604.2627	5.6271324	4269.9492	-0.00088625751
605.26208	5.6608706	4288.4136	-0.00088625751
606.26141	5.6946087	4291.7705	-0.00087282941
607.26074	5.7148519	4280.0205	-0.00087954348
608.26013	5.7452159	4273.3066	-0.00089297158
609.25946	5.7755804	4293.4487	-0.00087954348
610.25879	5.7991972	4286.7344	-0.00087954348
611.25818	5.8329353	4298.4844	-0.00087954348
612.25751	5.8666735	4288.4136	-0.00088625751
613.25684	5.8869166	4278.3423	-0.00087954348
614.25623	5.9206548	4288.4136	-0.00087954348
615.25555	5.9442716	4293.4487	-0.00087954348
616.25488	5.971262	4310.2339	-0.00088625751
617.25427	6.0050001	4291.7705	-0.00088625751
618.2536	6.0353646	4290.0918	-0.00089297158
619.25293	6.0623555	4301.8413	-0.00087954348
620.25232	6.0893459	4296.8057	-0.00089968566
621.25165	6.1197104	4290.0918	-0.00088625751
622.25098	6.1467009	4290.0918	-0.00087954348
623.25037	6.1770654	4283.3774	-0.00088625751
624.24969	6.2006822	4278.3423	-0.00088625751
625.24902	6.2310462	4293.4487	-0.00089297158
626.24841	6.2614107	4288.4136	-0.00089968566
627.24774	6.2884016	4280.0205	-0.00089297158
628.24707	6.3120179	4276.6636	-0.00088625751
629.24646	6.3457565	4295.1274	-0.00088625751
630.24579	6.3727469	4285.0562	-0.00089297158
631.24512	6.4064851	4306.877	-0.00089968566
632.24451	6.433476	4300.1626	-0.00088625751
633.24384	6.4604664	4288.4136	-0.00089297158
634.24316	6.4908309	4288.4136	-0.00089968566
635.24255	6.5144477	4286.7344	-0.00088625751
636.24188	6.5448117	4291.7705	-0.00089297158
637.24121	6.5751762	4301.8413	-0.00088625751
638.2406	6.598793	4291.7705	-0.00089297158
639.23993	6.6325312	4301.8413	-0.00087954348
640.23926	6.6628957	4320.3052	-0.00087954348
641.23865	6.6898861	4301.8413	-0.00087954348
642.23798	6.7202506	4308.5557	-0.00088625751
643.2373	6.747241	4301.8413	-0.00087954348
644.23669	6.7742319	4281.6992	-0.00088625751
645.23602	6.8012223	4291.7705	-0.00089297158
646.23535	6.8315868	4315.2695	-0.00087282941
647.23474	6.8619514	4293.4487	-0.00087282941
648.23407	6.8923154	4295.1274	-0.00088625751
649.2334	6.9159322	4296.8057	-0.00087282941
650.23279	6.9496703	4300.1626	-0.00088625751
651.23212	6.9699135	4293.4487	-0.00087954348
652.23145	7.000278	4308.5557	-0.00087954348
653.23083	7.0340161	4316.9478	-0.00087954348
654.23016	7.0610065	4308.5557	-0.00088625751
655.22949	7.0913711	4285.0562	-0.00088625751
656.22888	7.1149879	4290.0918	-0.00087954348
657.22821	7.1453524	4295.1274	-0.00088625751
658.22754	7.1757164	4301.8413	-0.00087954348
659.22693	7.2027073	4298.4844	-0.00087282941
660.22626	7.2330713	4301.8413	-0.00088625751
661.22559	7.2634358	4310.2339	-0.00087954348
662.22498	7.2803049	4296.8057	-0.00089297158
663.2243	7.3207908	4315.2695	-0.00088625751
664.22363	7.3477817	4308.5557	-0.00088625751
665.22302	7.3713984	4308.5557	-0.00087954348
666.22235	7.4051366	4306.877	-0.00087282941
667.22168	7.4287534	4295.1274	-0.00087954348
668.22107	7.4591174	4300.1626	-0.00087954348
669.2204	7.4894819	4321.9839	-0.00087954348
670.21973	7.5232201	4306.877	-0.00088625751
671.21912	7.5434632	4300.1626	-0.00088625751
672.21844	7.5738277	4316.9478	-0.00088625751
673.21777	7.6041918	4310.2339	-0.00089297158
674.21716	7.6311827	4305.1987	-0.00089968566
675.21649	7.6615467	4320.3052	-0.00088625751
676.21582	7.6851635	4300.1626	-0.00089297158
677.21521	7.715528	4311.9126	-0.00088625751
678.21454	7.7458925	4305.1987	-0.00087954348
679.21387	7.776257	4315.2695	-0.00088625751
680.21326	7.8066211	4308.5557	-0.00089297158
681.21259	7.8302379	4315.2695	-0.00087282941
682.21191	7.8572288	4313.5908	-0.00088625751
683.2113	7.8909669	4313.5908	-0.00089297158
684.21063	7.9179573	4300.1626	-0.00087954348
685.20996	7.9449482	4316.9478	-0.00087282941
686.20935	7.9786863	4293.4487	-0.00087954348
687.20868	8.0023031	4327.019	-0.00087954348
688.20801	8.029294	4318.627	-0.00086611533
689.2074	8.056284	4303.52	-0.00087954348
690.20673	8.0866489	4298.4844	-0.00087282941
691.20605	8.117013	4298.4844	-0.00089297158
692.20544	8.1440039	4318.627	-0.00087954348
693.20477	8.1743679	4316.9478	-0.00088625751
694.2041	8.1979847	4288.4136	-0.00088625751
695.20349	8.2283487	4303.52	-0.00087954348
696.20282	8.2587137	4298.4844	-0.00087282941
697.20215	8.2857037	4301.8413	-0.00087954348
698.20154	8.3194418	4303.52	-0.00088625751
699.20087	8.3430586	4291.7705	-0.00088625751
700.2002	8.3767977	4311.9126	-0.00088625751
701.19958	8.4037876	4288.4136	-0.00087282941
702.19891	8.4274044	4318.627	-0.00087954348
703.19824	8.4611425	4301.8413	-0.00088625751
704.19763	8.4881334	4315.2695	-0.00088625751
705.19696	8.5151243	4306.877	-0.00088625751
706.19629	8.5454884	4293.4487	-0.00087954348
707.19568	8.5724792	4301.8413	-0.00089297158
708.19501	8.6062174	4315.2695	-0.00088625751
709.19434	8.6298342	4313.5908	-0.00088625751
710.19373	8.6568241	4310.2339	-0.00088625751
711.19305	8.6905622	4303.52	-0.00088625751
712.19238	8.7175531	4330.376	-0.00088625751
713.19177	8.744544	4306.877	-0.00089297158
714.1911	8.771534	4313.5908	-0.00087954348
715.19043	8.801899	4303.52	-0.00087282941
716.18982	8.832263	4311.9126	-0.00088625751
717.18915	8.8592539	4286.7344	-0.00088625751
718.18848	8.892992	4310.2339	-0.00087954348
719.18787	8.9132347	4311.9126	-0.00088625751
720.18719	8.9435997	4301.8413	-0.00089297158
721.18652	8.9739637	4320.3052	-0.00089297158
722.18591	9.0009546	4316.9478	-0.00087954348
723.18524	9.0313187	4313.5908	-0.00088625751
724.18457	9.0616827	4303.52	-0.00087954348
725.18396	9.0886736	4330.376	-0.00088625751
726.18329	9.1224117	4313.5908	-0.00088625751
727.18262	9.1426544	4301.8413	-0.00088625751
728.18201	9.1763926	4306.877	-0.00088625751
729.18134	9.2000093	4295.1274	-0.00088625751
730.18066	9.2303743	4300.1626	-0.00087954348
731.18005	9.2607384	4316.9478	-0.00087954348
732.17938	9.2911034	4305.1987	-0.00087282941
733.17871	9.3147202	4295.1274	-0.00089297158
734.1781	9.3450842	4311.9126	-0.00088625751
735.17743	9.3754482	4310.2339	-0.00087954348
736.17676	9.4058132	4321.9839	-0.00087954348
737.17615	9.42943	4310.2339	-0.00087954348
738.17548	9.459794	4323.6621	-0.00088625751
739.1748	9.4834108	4296.8057	-0.00088625751
740.17419	9.5137749	4310.2339	-0.00088625751
741.17352	9.547513	4313.5908	-0.00088625751
742.17285	9.5711298	4316.9478	-0.00089297158
743.17224	9.5981207	4306.877	-0.00089297158
744.17157	9.6318588	4323.6621	-0.00089297158
745.1709	9.6588497	4311.9126	-0.00088625751
746.17029	9.6858406	4308.5557	-0.00087954348
747.16962	9.7195787	4310.2339	-0.00089297158
748.16895	9.7431955	4320.3052	-0.00089297158
749.16833	9.7769337	4290.0918	-0.00088625751
750.16766	9.8005505	4285.0562	-0.00088625751
751.16699	9.8275404	4300.1626	-0.00087954348
752.16638	9.8579054	4296.8057	-0.00089297158
753.16571	9.8882694	4316.9478	-0.00087954348
754.16504	9.9118862	4313.5908	-0.00088625751
755.16443	9.9456244	4316.9478	-0.00087954348
756.16376	9.9726152	4313.5908	-0.00088625751
757.16309	9.9996052	4293.4487	-0.00088625751
758.16248	10.033344	4316.9478	-0.00088625751
759.1618	10.05696	4316.9478	-0.00087954348
760.16113	10.087325	4321.9839	-0.00087954348
761.16052	10.114316	4327.019	-0.00087954348
762.15985	10.148054	4315.2695	-0.00088625751
763.15918	10.171671	4316.9478	-0.00087954348
764.15857	10.202035	4298.4844	-0.00088625751
765.1579	10.225652	4311.9126	-0.00087954348
766.15723	10.25939	4305.1987	-0.00089297158
767.15662	10.289754	4296.8057	-0.00087954348
768.15594	10.316745	4311.9126	-0.00088625751
769.15527	10.343736	4306.877	-0.00088625751
770.15466	10.370726	4296.8057	-0.00089297158
771.15399	10.401091	4303.52	-0.00087954348
772.15332	10.431455	4308.5557	-0.00088625751
773.15271	10.458446	4296.8057	-0.00087954348
774.15204	10.48881	4310.2339	-0.00088625751
775.15137	10.5158	4310.2339	-0.00089297158
776.15076	10.549539	4305.1987	-0.00087282941
777.15009	10.57653	4313.5908	-0.00088625751
778.14941	10.603519	4315.2695	-0.00088625751
779.1488	10.63051	4310.2339	-0.00089297158
780.14813	10.657501	4303.52	-0.00087954348
781.14746	10.684491	4296.8057	-0.00087954348
782.14685	10.714856	4311.9126	-0.00087954348
783.14618	10.74522	4300.1626	-0.00088625751
784.14551	10.772211	4295.1274	-0.00088625751
785.1449	10.795828	4316.9478	-0.00087954348
786.14423	10.836313	4308.5557	-0.00087282941
787.14355	10.856556	4298.4844	-0.00088625751
788.14294	10.886921	4291.7705	-0.00088625751
789.14227	10.913912	4305.1987	-0.00088625751
790.1416	10.944276	4296.8057	-0.00088625751
791.14099	10.971267	4316.9478	-0.00087954348
792.14032	10.998257	4313.5908	-0.00089297158
793.13965	11.028622	4301.8413	-0.00088625751
794.13904	11.06236	4291.7705	-0.00088625751
795.13837	11.08935	4311.9126	-0.00088625751
796.1377	11.116341	4305.1987	-0.00088625751
797.13708	11.143332	4308.5557	-0.00089297158
798.13641	11.173696	4273.3066	-0.00089297158
799.13574	11.197312	4290.0918	-0.00089297158
800.13513	11.23105	4311.9126	-0.00089968566
801.13446	11.254667	4321.9839	-0.00089297158
802.13379	11.288405	4301.8413	-0.00088625751
803.13318	11.315396	4303.52	-0.00089297158
804.13251	11.339013	4269.9492	-0.00089297158
805.13184	11.372751	4290.0918	-0.00087954348
806.13123	11.406489	4316.9478	-0.00087954348
807.13055	11.426732	4306.877	-0.00087954348
808.12988	11.457097	4301.8413	-0.00087282941
809.12927	11.490835	4315.2695	-0.00087282941
810.1286	11.517825	4301.8413	-0.00088625751
811.12793	11.544816	4296.8057	-0.00086611533
812.12732	11.571807	4278.3423	-0.00087954348
813.12665	11.598797	4288.4136	-0.00089297158
814.12598	11.632535	4301.8413	-0.00088625751
815.12537	11.656152	4316.9478	-0.00089297158
816.12469	11.683143	4296.8057	-0.00087282941
817.12402	11.720255	4306.877	-0.00087282941
818.12341	11.743872	4306.877	-0.00086611533
819.12274	11.770863	4283.3774	-0.00088625751
820.12207	11.801227	4303.52	-0.00087954348
821.12146	11.828218	4269.9492	-0.00087954348
822.12079	11.858582	4291.7705	-0.00087954348
823.12012	11.888946	4305.1987	-0.00088625751
824.11951	11.909189	4301.8413	-0.00088625751
825.11884	11.942927	4293.4487	-0.00089297158
826.11816	11.973291	4301.8413	-0.00087954348
827.11755	11.996908	4301.8413	-0.00088625751
828.11688	12.03402	4286.7344	-0.00089297158
829.11621	12.057637	4300.1626	-0.00087954348
830.1156	12.088001	4293.4487	-0.00088625751
831.11493	12.114992	4269.9492	-0.00087954348
832.11426	12.145356	4291.7705	-0.00089297158
833.11365	12.168973	4280.0205	-0.00089297158
834.11298	12.199338	4295.1274	-0.00089297158
835.1123	12.229702	4280.0205	-0.00087954348
836.11169	12.260066	4293.4487	-0.00088625751
837.11102	12.283683	4283.3774	-0.00088625751
838.11035	12.317421	4285.0562	-0.00087954348
839.10974	12.341038	4288.4136	-0.00088625751
840.10907	12.371403	4280.0205	-0.00087954348
841.1084	12.398393	4285.0562	-0.00087954348
842.10779	12.432131	4291.7705	-0.00087954348
843.10712	12.459122	4288.4136	-0.00087954348
844.10645	12.486113	4276.6636	-0.00087954348
845.10583	12.519851	4288.4136	-0.00088625751
846.10516	12.543468	4286.7344	-0.00087282941
847.10449	12.573832	4278.3423	-0.00087954348
848.10388	12.604197	4283.3774	-0.00087954348
849.10321	12.631186	4273.3066	-0.00087954348
850.10254	12.661551	4280.0205	-0.00089297158
851.10193	12.681794	4268.271	-0.00088625751
852.10126	12.715532	4274.9854	-0.00088625751
853.10059	12.745896	4291.7705	-0.00088625751
854.09998	12.769513	4285.0562	-0.00087282941
855.0993	12.796504	4269.9492	-0.00087954348
856.09863	12.830242	4301.8413	-0.00088625751
857.09802	12.850485	4290.0918	-0.00087282941
858.09735	12.884223	4293.4487	-0.00088625751
859.09668	12.917962	4285.0562	-0.00087282941
860.09607	12.941578	4266.5923	-0.00087282941
861.0954	12.968569	4285.0562	-0.00087954348
862.09473	13.002307	4303.52	-0.00089297158
863.09412	13.025924	4269.9492	-0.00088625751
864.09344	13.052915	4290.0918	-0.00087954348
865.09277	13.086653	4271.6284	-0.00087282941
866.09216	13.113644	4249.8071	-0.00088625751
867.09149	13.144008	4295.1274	-0.00088625751
868.09082	13.174372	4300.1626	-0.00087954348
869.09021	13.201363	4290.0918	-0.00086611533
870.08954	13.228354	4283.3774	-0.00088625751
871.08887	13.258718	4276.6636	-0.00087954348
872.08826	13.282334	4271.6284	-0.00089968566
873.08759	13.312698	4285.0562	-0.00089297158
874.08691	13.339689	4256.5215	-0.00087954348
875.0863	13.373427	4283.3774	-0.00088625751
876.08563	13.400418	4274.9854	-0.00087954348
877.08496	13.430782	4276.6636	-0.00088625751
878.08435	13.457773	4286.7344	-0.00088625751
879.08368	13.48139	4254.8428	-0.00087954348
880.08301	13.515128	4266.5923	-0.00087282941
881.0824	13.542119	4280.0205	-0.00088625751
882.08173	13.572483	4271.6284	-0.00087282941
883.08105	13.599474	4264.9141	-0.00088625751
884.08044	13.626464	4273.3066	-0.00087282941
885.07977	13.653455	4288.4136	-0.00089297158
886.0791	13.683819	4258.2002	-0.00089297158
887.07849	13.707436	4258.2002	-0.00089968566
888.07782	13.741174	4271.6284	-0.00088625751
889.07715	13.774913	4264.9141	-0.00088625751
890.07654	13.79853	4278.3423	-0.00088625751
891.07587	13.828894	4268.271	-0.00089297158
892.0752	13.855885	4264.9141	-0.00087954348
893.07458	13.882874	4253.1641	-0.00089968566
894.07391	13.916613	4258.2002	-0.00088625751
895.07324	13.943604	4253.1641	-0.00088625751
896.07263	13.970594	4256.5215	-0.00088625751
897.07196	13.997584	4268.271	-0.00089297158
898.07129	14.027949	4264.9141	-0.00088625751
899.07068	14.058313	4280.0205	-0.00088625751
900.07001	14.088677	4258.2002	-0.00090639974
901.06934	14.112294	4241.415	-0.00088625751
902.06873	14.139285	4248.1289	-0.00089968566
903.06805	14.169649	4256.5215	-0.00089297158
904.06738	14.203388	4251.4858	-0.00087954348
905.06677	14.230378	4261.5571	-0.00087954348
906.0661	14.253995	4249.8071	-0.00088625751
907.06543	14.28436	4271.6284	-0.00088625751
908.06482	14.31135	4244.772	-0.00089297158
909.06415	14.345088	4244.772	-0.00089297158
910.06348	14.372079	4244.772	-0.00089297158
911.06287	14.39907	4244.772	-0.00089297158
912.06219	14.42606	4244.772	-0.00089297158
913.06152	14.456425	4258.2002	-0.00088625751
914.06091	14.483415	4261.5571	-0.00089297158
915.06024	14.51378	4259.8784	-0.00088625751
916.05957	14.54077	4248.1289	-0.00089297158
917.05896	14.574509	4243.0933	-0.00088625751
918.05829	14.598125	4254.8428	-0.00087954348
919.05762	14.631864	4264.9141	-0.00087954348
920.05701	14.652106	4256.5215	-0.00088625751
921.05634	14.689219	4249.8071	-0.00087282941
922.05566	14.712835	4261.5571	-0.00087954348
923.05505	14.743199	4251.4858	-0.00087954348
924.05438	14.773563	4227.9868	-0.00088625751
925.05371	14.800554	4243.0933	-0.00087954348
926.0531	14.827545	4238.0576	-0.00088625751
927.05243	14.861283	4239.7358	-0.00087954348
928.05176	14.8849	4234.7007	-0.00087282941
929.05115	14.91189	4243.0933	-0.00088625751
930.05048	14.942255	4244.772	-0.00089297158
931.0498	14.969245	4244.772	-0.00088625751
932.04919	14.996236	4243.0933	-0.00089297158
933.04852	15.026601	4236.3789	-0.00088625751
934.04785	15.060339	4243.0933	-0.00087954348
935.04724	15.087329	4239.7358	-0.00087954348
936.04657	15.110946	4226.3081	-0.00088625751
937.0459	15.144684	4244.772	-0.00088625751
938.04529	15.168301	4219.5942	-0.00087282941
939.04462	15.195292	4206.166	-0.00087954348
940.04395	15.22903	4214.5586	-0.00087282941
941.04333	15.256021	4243.0933	-0.00089968566
942.04266	15.286385	4227.9868	-0.00089297158
943.04199	15.313375	4216.2373	-0.00088625751
944.04138	15.34374	4221.2725	-0.00087954348
945.04071	15.37073	4233.022	-0.00089297158
946.04004	15.401094	4249.8071	-0.00087954348
947.03943	15.428085	4224.6299	-0.00088625751
948.03876	15.455076	4226.3081	-0.00089968566
949.03809	15.488814	4216.2373	-0.00088625751
950.03748	15.515804	4204.4873	-0.00088625751
951.0368	15.539421	4222.9512	-0.00088625751
952.03613	15.569786	4231.3438	-0.00087954348
953.03552	15.60015	4222.9512	-0.00088625751
954.03485	15.627141	4197.7734	-0.00088625751
955.03418	15.657505	4221.2725	-0.00088625751
956.03357	15.681122	4212.8804	-0.00089968566
957.0329	15.711486	4211.2017	-0.00089297158
958.03223	15.741851	4180.9883	-0.00088625751
959.03162	15.768841	4206.166	-0.00088625751
960.03094	15.799206	4214.5586	-0.00089297158
961.03027	15.826197	4219.5942	-0.00089297158
962.02966	15.853187	4211.2017	-0.00087954348
963.02899	15.883552	4197.7734	-0.00088625751
964.02832	15.910542	4194.4165	-0.00087282941
965.02771	15.940907	4199.4521	-0.00089297158
966.02704	15.967896	4219.5942	-0.00089297158
967.02637	15.998261	4209.5234	-0.00087282941
968.02576	16.028625	4211.2017	-0.00087954348
969.02509	16.052242	4194.4165	-0.00087954348
970.02441	16.085981	4175.9526	-0.00089297158
971.0238	16.11297	4174.2739	-0.00087954348
972.02313	16.143335	4194.4165	-0.00088625751
973.02246	16.163578	4186.0239	-0.00089297158
974.02185	16.200691	4189.3809	-0.00088625751
975.02118	16.220934	4169.2388	-0.00087282941
976.02051	16.254671	4167.5601	-0.00088625751
977.0199	16.285036	4164.2031	-0.00087954348
978.01923	16.312027	4170.917	-0.00088625751
979.01855	16.339018	4167.5601	-0.00088625751
980.01794	16.372755	4170.917	-0.00087282941
981.01727	16.399746	4177.6313	-0.00088625751
982.0166	16.426737	4145.7393	-0.00088625751
983.01599	16.453728	4159.1675	-0.00089297158
984.01532	16.487465	4162.5249	-0.00088625751
985.01465	16.514456	4152.4536	-0.00087282941
986.01404	16.538073	4147.418	-0.00089297158
987.01337	16.571812	4142.3823	-0.00089297158
988.0127	16.598801	4135.6685	-0.00088625751
989.01208	16.625792	4152.4536	-0.00088625751
990.01141	16.659531	4149.0967	-0.00087954348
991.01074	16.679773	4150.7749	-0.00087954348
992.01013	16.716885	4139.0254	-0.00087282941
993.00946	16.740501	4120.5615	-0.00088625751
994.00879	16.764118	4113.8472	-0.00087954348
995.00818	16.797857	4135.6685	-0.00089297158
996.00751	16.824848	4128.9541	-0.00088625751
997.00684	16.855211	4105.4551	-0.00088625751
998.00623	16.882202	4115.5264	-0.00088625751
999.00555	16.909193	4102.0981	-0.00087954348
1000.0049	16.942932	4095.3835	-0.00089297158
1001.0043	16.969921	4117.2046	-0.00089297158
1002.0036	16.996912	4073.563	-0.00089968566
1003.0029	17.027277	4083.6338	-0.00087282941
1004.0023	17.054268	4080.2769	-0.00089297158
1005.0016	17.088005	4085.3127	-0.00088625751
1006.001	17.114996	4071.8845	-0.00088625751
1007.0004	17.138613	4078.5984	-0.00087954348
1007.9997	17.168978	4058.4565	-0.00088625751
1008.999	17.195969	4045.0283	-0.00088625751
1009.9984	17.226332	4031.6001	-0.00088625751
1010.9977	17.260071	4063.4917	-0.00088625751
1011.9971	17.280313	4053.4209	-0.00088625751
1012.9965	17.310678	4053.4209	-0.00088625751
1013.9958	17.344416	4026.5647	-0.00088625751
1014.9951	17.374781	4021.5293	-0.00088625751
1015.9945	17.398397	4018.1719	-0.00088625751
1016.9938	17.425388	3991.3157	-0.00089968566
1017.9932	17.455751	4011.458	-0.00088625751
1018.9926	17.482742	4004.7437	-0.00089297158
1019.9919	17.509733	3992.9941	-0.00089297158
1020.9912	17.540098	3996.3513	-0.00089297158
1021.9906	17.570461	3986.2803	-0.00088625751
1022.9899	17.594078	3987.9587	-0.00087954348
1023.9893	17.624443	3979.5662	-0.00087954348
1024.9886	17.651434	3976.209	-0.00088625751
1025.988	17.685173	3954.3882	-0.00088625751
1026.9873	17.712162	3964.4595	-0.00088625751
1027.9867	17.742527	3954.3882	-0.00088625751
1028.9861	17.769518	3949.3528	-0.00087282941
1029.9854	17.803255	3932.5676	-0.00087954348
1030.9847	17.826872	3922.4963	-0.00089297158
1031.9841	17.857237	3912.4253	-0.00088625751
1032.9834	17.887602	3907.3896	-0.00087282941
1033.9828	17.911219	3890.6045	-0.00087954348
1034.9822	17.941582	3892.2832	-0.00088625751
1035.9814	17.965199	3880.5334	-0.00088625751
1036.9808	17.998938	3873.8193	-0.00088625751
1037.9802	18.025928	3863.7483	-0.00087282941
1038.9795	18.052919	3850.3201	-0.00087954348
1039.9789	18.083282	3833.5349	-0.00089297158
1040.9783	18.110273	3838.5706	-0.00088625751
1041.9775	18.137264	3835.2134	-0.00088625751
1042.9769	18.164255	3811.7141	-0.00089297158
1043.9763	18.201366	3816.7498	-0.00088625751
1044.9756	18.228357	3794.929	-0.00087954348
1045.975	18.255348	3769.7512	-0.00088625751
1046.9744	18.285713	3778.1438	-0.00087282941
1047.9736	18.312702	3761.3586	-0.00087954348
1048.973	18.336319	3734.5022	-0.00089297158
1049.9724	18.373432	3739.5378	-0.00089297158
1050.9717	18.397049	3731.1453	-0.00087954348
1051.9711	18.427412	3699.2537	-0.00087282941
1052.9705	18.451029	3690.8611	-0.00088625751
1053.9697	18.484768	3667.3618	-0.00088625751
1054.9691	18.515133	3652.2551	-0.00088625751
1055.9685	18.535376	3652.2551	-0.00089297158
1056.9678	18.569113	3637.1484	-0.00088625751
1057.9672	18.596104	3618.6846	-0.00088625751
1058.9666	18.623095	3617.0061	-0.00088625751
1059.9658	18.656834	3601.8994	-0.00087282941
1060.9652	18.683823	3571.686	-0.00088625751
1061.9646	18.710814	3541.4729	-0.00088625751
1062.9639	18.741179	3529.7231	-0.00088625751
1063.9633	18.771544	3501.1882	-0.00089297158
1064.9626	18.791786	3469.2964	-0.00089297158
1065.9619	18.825523	3445.7971	-0.00087954348
1066.9613	18.855888	3417.2625	-0.00088625751
1067.9607	18.882879	3408.8699	-0.00089968566
1068.96	18.913244	3373.6211	-0.00088625751
1069.9594	18.936861	3328.301	-0.00089297158
1070.9587	18.970598	3291.3738	-0.00089297158
1071.958	18.997589	3257.8032	-0.00087954348
1072.9574	19.027954	3237.6611	-0.00087282941
1073.9568	19.051571	3173.8774	-0.00087954348
1074.9561	19.085308	3106.7366	-0.00089297158
1075.9554	19.112299	3009.3826	-0.00087954348
1076.9548	19.142664	2903.636	-0.00089297158
1077.9541	19.169653	2744.1768	-0.00087954348
1078.9535	19.196644	2611.574	-0.00089297158
1079.9529	19.220261	2470.5784	-0.00087954348
1080.9521	19.254	2336.2969	-0.00087954348
1081.9515	19.284365	2243.9785	-0.00087954348
1082.9509	19.311354	2149.9812	-0.00089968566
1083.9502	19.341719	2072.7695	-0.00089968566
1084.9496	19.372084	2007.3073	-0.00089297158
1085.949	19.3957	1920.0244	-0.00088625751
1086.9482	19.429438	1837.777	-0.00088625751
1087.9476	19.453054	1768.9578	-0.00088625751
1088.947	19.486794	1700.1385	-0.00088625751
1089.9463	19.513784	1629.6409	-0.00087954348
1090.9457	19.540773	1565.8571	-0.00087954348
1091.9451	19.567764	1486.9667	-0.00088625751
1092.9443	19.594755	1443.3253	-0.00088625751
1093.9437	19.631868	1379.5416	-0.00089968566
1094.9431	19.652111	1315.7578	-0.00089297158
1095.9424	19.682474	1246.9387	-0.00089297158
1096.9418	19.712839	1198.2616	-0.00089297158
1097.9412	19.73983	1127.7639	-0.00089968566
1098.9404	19.770195	1079.0869	-0.00088625751
1099.9398	19.793812	1042.1594	-0.00088625751
1100.9392	19.824175	964.94763	-0.00089968566
1101.9385	19.857914	906.19952	-0.00088625751
1102.9379	19.884905	852.48694	-0.00088625751
1103.9373	19.911894	770.23956	-0.00089297158
1104.9365	19.938885	708.1344	-0.00087954348
1105.9359	19.965876	640.99365	-0.00089968566
1106.9353	19.999615	577.21002	-0.00088625751
1107.9346	20.023232	516.78339	-0.00089297158
1108.934	20.053595	458.03519	-0.00088625751
1109.9333	20.080585	377.46634	-0.00089968566
1110.9326	20.114325	335.50339	-0.00087954348
1111.932	20.137941	290.18338	-0.00088625751
1112.9314	20.164932	241.50638	-0.00087954348
1113.9307	20.198669	211.29306	-0.00087954348
1114.9301	20.22566	167.6516	-0.00088625751
1115.9294	20.256025	100.51087	-0.00089297158
1116.9287	20.286388	21.620525	-0.00087954348
1117.9281	20.306631	8.1923819	-0.00088625751
1118.9275	20.34037	4.8353453	-0.00089297158
1119.9268	20.370735	11.549417	-0.00087954348
1120.9261	20.397724	8.1923819	-0.00087954348
1121.9255	20.424715	-0.20020857	-0.00089297158
1122.0254	20.428089	3.1568274	-0.00087954348